2025-04-08 11:00:35,146 ERROR: Exception on /auth/register [POST] [in /Users/asanbeksamudin/Documents/projects/mine/python/flask/microblog/venv/lib/python3.12/site-packages/flask/app.py:1414]
Traceback (most recent call last):
  File "/Users/asanbeksamudin/Documents/projects/mine/python/flask/microblog/venv/lib/python3.12/site-packages/sqlalchemy/engine/base.py", line 1964, in _exec_single_context
    self.dialect.do_execute(
  File "/Users/asanbeksamudin/Documents/projects/mine/python/flask/microblog/venv/lib/python3.12/site-packages/sqlalchemy/engine/default.py", line 942, in do_execute
    cursor.execute(statement, parameters)
sqlite3.OperationalError: no such table: user

The above exception was the direct cause of the following exception:

Traceback (most recent call last):
  File "/Users/asanbeksamudin/Documents/projects/mine/python/flask/microblog/venv/lib/python3.12/site-packages/flask/app.py", line 2190, in wsgi_app
    response = self.full_dispatch_request()
               ^^^^^^^^^^^^^^^^^^^^^^^^^^^^
  File "/Users/asanbeksamudin/Documents/projects/mine/python/flask/microblog/venv/lib/python3.12/site-packages/flask/app.py", line 1486, in full_dispatch_request
    rv = self.handle_user_exception(e)
         ^^^^^^^^^^^^^^^^^^^^^^^^^^^^^
  File "/Users/asanbeksamudin/Documents/projects/mine/python/flask/microblog/venv/lib/python3.12/site-packages/flask/app.py", line 1484, in full_dispatch_request
    rv = self.dispatch_request()
         ^^^^^^^^^^^^^^^^^^^^^^^
  File "/Users/asanbeksamudin/Documents/projects/mine/python/flask/microblog/venv/lib/python3.12/site-packages/flask/app.py", line 1469, in dispatch_request
    return self.ensure_sync(self.view_functions[rule.endpoint])(**view_args)
           ^^^^^^^^^^^^^^^^^^^^^^^^^^^^^^^^^^^^^^^^^^^^^^^^^^^^^^^^^^^^^^^^^
  File "/Users/asanbeksamudin/Documents/projects/mine/python/flask/microblog/microblog/app/auth/routes.py", line 42, in register
    if form.validate_on_submit():
       ^^^^^^^^^^^^^^^^^^^^^^^^^
  File "/Users/asanbeksamudin/Documents/projects/mine/python/flask/microblog/venv/lib/python3.12/site-packages/flask_wtf/form.py", line 86, in validate_on_submit
    return self.is_submitted() and self.validate(extra_validators=extra_validators)
                                   ^^^^^^^^^^^^^^^^^^^^^^^^^^^^^^^^^^^^^^^^^^^^^^^^
  File "/Users/asanbeksamudin/Documents/projects/mine/python/flask/microblog/venv/lib/python3.12/site-packages/wtforms/form.py", line 330, in validate
    return super().validate(extra)
           ^^^^^^^^^^^^^^^^^^^^^^^
  File "/Users/asanbeksamudin/Documents/projects/mine/python/flask/microblog/venv/lib/python3.12/site-packages/wtforms/form.py", line 147, in validate
    if not field.validate(self, extra):
           ^^^^^^^^^^^^^^^^^^^^^^^^^^^
  File "/Users/asanbeksamudin/Documents/projects/mine/python/flask/microblog/venv/lib/python3.12/site-packages/wtforms/fields/core.py", line 234, in validate
    stop_validation = self._run_validation_chain(form, chain)
                      ^^^^^^^^^^^^^^^^^^^^^^^^^^^^^^^^^^^^^^^
  File "/Users/asanbeksamudin/Documents/projects/mine/python/flask/microblog/venv/lib/python3.12/site-packages/wtforms/fields/core.py", line 254, in _run_validation_chain
    validator(form, self)
  File "/Users/asanbeksamudin/Documents/projects/mine/python/flask/microblog/microblog/app/auth/forms.py", line 25, in validate_username
    user = User.query.filter_by(username=username.data).first()
           ^^^^^^^^^^^^^^^^^^^^^^^^^^^^^^^^^^^^^^^^^^^^^^^^^^^^
  File "/Users/asanbeksamudin/Documents/projects/mine/python/flask/microblog/venv/lib/python3.12/site-packages/sqlalchemy/orm/query.py", line 2759, in first
    return self.limit(1)._iter().first()  # type: ignore
           ^^^^^^^^^^^^^^^^^^^^^
  File "/Users/asanbeksamudin/Documents/projects/mine/python/flask/microblog/venv/lib/python3.12/site-packages/sqlalchemy/orm/query.py", line 2858, in _iter
    result: Union[ScalarResult[_T], Result[_T]] = self.session.execute(
                                                  ^^^^^^^^^^^^^^^^^^^^^
  File "/Users/asanbeksamudin/Documents/projects/mine/python/flask/microblog/venv/lib/python3.12/site-packages/sqlalchemy/orm/session.py", line 2365, in execute
    return self._execute_internal(
           ^^^^^^^^^^^^^^^^^^^^^^^
  File "/Users/asanbeksamudin/Documents/projects/mine/python/flask/microblog/venv/lib/python3.12/site-packages/sqlalchemy/orm/session.py", line 2251, in _execute_internal
    result: Result[Any] = compile_state_cls.orm_execute_statement(
                          ^^^^^^^^^^^^^^^^^^^^^^^^^^^^^^^^^^^^^^^^
  File "/Users/asanbeksamudin/Documents/projects/mine/python/flask/microblog/venv/lib/python3.12/site-packages/sqlalchemy/orm/context.py", line 306, in orm_execute_statement
    result = conn.execute(
             ^^^^^^^^^^^^^
  File "/Users/asanbeksamudin/Documents/projects/mine/python/flask/microblog/venv/lib/python3.12/site-packages/sqlalchemy/engine/base.py", line 1416, in execute
    return meth(
           ^^^^^
  File "/Users/asanbeksamudin/Documents/projects/mine/python/flask/microblog/venv/lib/python3.12/site-packages/sqlalchemy/sql/elements.py", line 523, in _execute_on_connection
    return connection._execute_clauseelement(
           ^^^^^^^^^^^^^^^^^^^^^^^^^^^^^^^^^^
  File "/Users/asanbeksamudin/Documents/projects/mine/python/flask/microblog/venv/lib/python3.12/site-packages/sqlalchemy/engine/base.py", line 1638, in _execute_clauseelement
    ret = self._execute_context(
          ^^^^^^^^^^^^^^^^^^^^^^
  File "/Users/asanbeksamudin/Documents/projects/mine/python/flask/microblog/venv/lib/python3.12/site-packages/sqlalchemy/engine/base.py", line 1843, in _execute_context
    return self._exec_single_context(
           ^^^^^^^^^^^^^^^^^^^^^^^^^^
  File "/Users/asanbeksamudin/Documents/projects/mine/python/flask/microblog/venv/lib/python3.12/site-packages/sqlalchemy/engine/base.py", line 1983, in _exec_single_context
    self._handle_dbapi_exception(
  File "/Users/asanbeksamudin/Documents/projects/mine/python/flask/microblog/venv/lib/python3.12/site-packages/sqlalchemy/engine/base.py", line 2352, in _handle_dbapi_exception
    raise sqlalchemy_exception.with_traceback(exc_info[2]) from e
  File "/Users/asanbeksamudin/Documents/projects/mine/python/flask/microblog/venv/lib/python3.12/site-packages/sqlalchemy/engine/base.py", line 1964, in _exec_single_context
    self.dialect.do_execute(
  File "/Users/asanbeksamudin/Documents/projects/mine/python/flask/microblog/venv/lib/python3.12/site-packages/sqlalchemy/engine/default.py", line 942, in do_execute
    cursor.execute(statement, parameters)
sqlalchemy.exc.OperationalError: (sqlite3.OperationalError) no such table: user
[SQL: SELECT user.id AS user_id, user.username AS user_username, user.email AS user_email, user.password_hash AS user_password_hash, user.about_me AS user_about_me, user.last_seen AS user_last_seen 
FROM user 
WHERE user.username = ?
 LIMIT ? OFFSET ?]
[parameters: ('asanbek.best', 1, 0)]
(Background on this error at: https://sqlalche.me/e/20/e3q8)
